<?xml version="1.0"?>
<robot xmlns:xacro="http://www.ros.org/wiki/xacro">

  <xacro:macro name="tractor_wheel" params="name x y">
    <link name="${name}">
      <visual>
        <origin xyz="0 0 0" rpy="1.5708 0 0"/>
        <geometry>
          <cylinder radius="${wheel_radius}" length="${wheel_width}"/>
        </geometry>
        <material name="black"/>
      </visual>

      <collision>
        <origin xyz="0 0 0" rpy="1.5708 0 0"/>
        <geometry>
          <cylinder radius="${wheel_radius}" length="${wheel_width}"/>
        </geometry>
      </collision>

      <inertial>
        <origin xyz="0 0 0" rpy="0 0 0"/>
        <mass value="2.0"/>
        <inertia
          ixx="0.02" ixy="0.0" ixz="0.0"
          iyy="0.02" iyz="0.0"
          izz="0.02"/>
      </inertial>
    </link>

    <joint name="${name}_joint" type="continuous">
      <parent link="base_link"/>
      <child link="${name}"/>
      <origin xyz="${x} ${y} ${wheel_z}" rpy="0 0 0"/>
      <axis xyz="0 1 0"/>
    </joint>
  </xacro:macro>

  <xacro:macro name="tractor_core">
    <link name="base_footprint"/>

    <joint name="base_footprint_joint" type="fixed">
      <parent link="base_footprint"/>
      <child link="base_link"/>
      <origin xyz="0 0 0.18" rpy="0 0 0"/>
    </joint>

    <link name="base_link">
      <visual>
        <origin xyz="0 0 0" rpy="0 0 0"/>
        <geometry>
          <box size="${base_length} ${base_width} ${base_height}"/>
        </geometry>
        <material name="green"/>
      </visual>

      <collision>
        <origin xyz="0 0 0" rpy="0 0 0"/>
        <geometry>
          <box size="${base_length} ${base_width} ${base_height}"/>
        </geometry>
      </collision>

      <inertial>
        <origin xyz="0 0 0" rpy="0 0 0"/>
        <mass value="40.0"/>
        <inertia
          ixx="3.0" ixy="0.0" ixz="0.0"
          iyy="3.0" iyz="0.0"
          izz="3.0"/>
      </inertial>
    </link>

    <xacro:tractor_wheel name="front_left_wheel" x="${wheel_x_front}" y="${wheel_y}"/>
    <xacro:tractor_wheel name="front_right_wheel" x="${wheel_x_front}" y="${-wheel_y}"/>
    <xacro:tractor_wheel name="rear_left_wheel" x="${wheel_x_rear}" y="${wheel_y}"/>
    <xacro:tractor_wheel name="rear_right_wheel" x="${wheel_x_rear}" y="${-wheel_y}"/>
  </xacro:macro>

</robot>
